# 前言

当设计一段代码时，作为程序员的我们，应同时以一名使用者的身份思考。不仅应该考虑改代码可能会出现的异常，还要想，使用该代码时希望其具有的功能。对于异常处理，本章仅写了十页，真是简洁啊。

# 7.1抛出异常

异常处理机制有两个主要成分：异常的**识别与发出**，以及**异常的处理方式**。
任何函数在运行时都可能产生异常以及处理异常。异常出现之后，正常的程序执行会被悬置（suspend）。与此同时，异常处理机制开始搜寻程序中有能力处理这一异常的地点。异常被处理完毕之后，程序的执行便会重新激活（resume），从异常处理点接续执行下去。
c++通过throw表达式产生一个异常。感觉说是抛出一个异常更好。

```c++
inline void Triangular_iterator::
check_integrity(){
    if(_index >= Triangular::_max_elem)
        throw iterator_overflow(_index,Triangular::_max_elems);
    if(_index >= Triangular::_elem.size())
        Triangular::gen_elements(_index+1);
}
```

这是4.6节中的代码。iterator_overflow应该是作者自己定义的一个异常类。throw抛出的是个异常类对象。书中说“何谓抛出了一个异常？所谓异常是某种对象。”当然throw也可抛出整数或字符串中的对象。

```c++
throw 42；
throw “panic：no buffer！”
```

大部分时候，被抛出的异常都属于特定的异常类。

```c++
class iterator_overflow{
public:
    iterator_overflow(int index,int max):_index(index),_max(max){ }
    int index(){ return _index; }
    int max(){ return _max;}
    void what_happned(ostream &os=cerr){
        os << "Internal error:current index " << _index << "exceeds maximum bound:" << _max;
    }
private:
    int _index;
    int _max;
};
```

其用以保存异常的性质以便在不同程序的不同调用点上相互传递这些性质。当然可以明确抛出对象的名称：

```c++
iterator_overflow ex(_index,Triangular::_max_elems);
throw ex;
```

# 7.2捕捉异常

感觉这儿讲的不好，应该跟try一起讲。
catch不能脱离try而单独存在。
我们可以利用单一或连串的catch子句来捕捉被抛出的异常对象。写下例子：
```c++
extern void long_message(const char *);
extern string err_messages[];
extern ostream long_file;
bool some_function(){
    bool status=true;
    //...假设我们抵达此处，此处应有try。
    catch(int errno){
        log_message(err_message[errno]);
        status=false;
    }
    catch(const char *str){
        log_message(str);
        status=false;
    }
    catch(iterator_overflow &iof){
        iof.what_happened(log_file);
        status=false;
    }
    return status;
}
```


对于 
```c++
throw 42； 
throw "panic：no buffer："；
throw iterator_overflow(_index,Triangular::_max_elems);
```

异常对象的型别会被拿来逐一地和每个catch子句比较，如果型别符合便执行相应catch中的内容，执行完毕后，程序会接在最后一个catch子句后的第一句开始执行，本例中为return status;

我试了下：

```c++
#include<iostream>
using namespace std;
int main(){
    cout<<"hello"<<endl;
    try{
        throw 12;
        cout<<"try"<<endl;
    }catch(int n){
        cout<<n<<endl; throw;
    }catch(int k){
        cout<<k<<endl;
    }
}
```

虽然可以运行，但是会卡住。编译器提示
```
hello
12
terminate called after throwing an instance of 'int'
bash: line 7:  8044 Aborted                 
(core dumped) ./a.out
```

而第二个catch并未接受。我又试了下：

```c++
#include "stdafx.h"
#include<iostream>
using namespace std;
void kk(){
    try{
        throw 12;
    }catch(int n){
        cout<<n<<endl; throw;
    }
}
int main(){
    cout<<"hello"<<endl;
    try{
        kk();
    }catch(int k){
        cout<<k<<endl;
    }

    system("pause");
}
```

嗯，这次对了

```
hello
12
12
```

如果我们想要捕捉任何型别的异常，可以使用一网打尽的方式，只需要在异常声明部分指定省略符号(...)即可。

```c++
catch(...){
//......
}
```

对于这个的使用限制是：当它跟多个catch子句一起用时，它必须是最后一个。catch(...)经常与重新抛出表达式结合使用。

# 7.3提炼异常

本节分为两部分。第一部分讲解的是异常的处理方式。第二部分涉及的是异常处理部分语句的排放。

关于try和catch上节说过了，应该连在一起。

以下是本节的例子：

在first和last内寻找elem。迭代操作可能会引发iterator_overflow异常。

```c++
bool has_elem( Triangular_iterator first, Triangular_iterator last, int elem ){
    bool status = true;
    try {
        while ( first != last )
        {
            if ( *first == elem )
                return status;
            ++first;
        }
    }
    // try 块内的程序代码执行时，如果有任何异常抛出，
    // 我们只捕捉其中类型为iterator_overflow的异常。
    catch ( iterator_overflow &iof )
    {
        log_message( iof.what_happened() );
        log_message( "Check if iterators address some container" );
    }

    status = false;
    return status;
}

inline int Triangular_iterator::
operator*(){
    check_integrity();
    return Triangular::elems[_index];
}
inline void Triangular_iterator::
check_integrity(){
    if(_index>=Triangular::_max_elems)
        throw iterator_overflow_index,Triangular::_max_elems);
    //......
}
```

第一个问题便是当check_integrity()throw出个异常时，程序是怎样运行的？不看书上的讲解，看下primer:
“在复杂的系统中，程序的执行路径也许在遇到抛出异常的代码之前，就已经经过了多个try块。例如，一个try块可能调用了包含另一个try块的函数，它的try块又调用了含有try块的另一个函数，如此类推。寻找处理代码的过程与函数调用链刚好相反。抛出一个异常时，首先要搜索的是抛出异常的函数。如果没有找到匹配的catch，则终止这个函数的执行，并在调用这个函数的函数中寻找相配的catch。如果仍然没有找到相应的处理代码，该函数同样要终止，搜索调用它的函数。如此类推，继续按执行路径回退。直到找到适当类型的catch为止。如果不存在处理该异常的catch子句。程序的运行就要跳转到名为terminate的标准库函数，该函数在exception头文件中定义。这个标准库函数的行为依赖于系统。通常情况下，它的执行将导致程序非正常退出。” 在c++中，任何一个被抛出的异常都会被处理。

第二个问题，程序中何处该放置try块，try块内应该放哪些语句？嗯，这是个闹心的问题。注意上述中，throw与相应的catch间的语句都不会执行，异常处理完毕，程序紧接最后一个catch开始执行。为什么不将check_integrity()置于try内呢？重看operator*()，若check_integrity()抛出了异常，那么return语句一定不会执行，也就是说在安全的情况下，return语句便会执行。此时的_index是正确的，但是若将check_integrity()置于try中，那么，相应的catch子句中必须考虑应该如何对待_index，以使_elem[index]有效，所以......现在作者给分析了下has_elem(),其功能是检验elem是否位于first和last之间，为此要不断累加first，并对其提领。first的累加操作和提领操作是has_elem()的实现细节。而iterator_overflow则是该实现内容的一个方面。而has_elem()的调用者只想知道elem到底在不在first和last内。其它的不想知道，所以异常的处理应置于has_elem()内部。对于这一节的第二个问题还是不很清楚，应该增加编程经验。


# 7.4局部资源管理
c++无java的垃圾回收装置，所以内存资源需要我们自己管理，要做到new出来的内存在不用时都被delete掉，看下面一段代码。
```c++
extern Mutex m;
void f(){
    int *p=new int;
    m.acquire();
    process(p);
    m.release();
    delete p;
}
```
该代码有个隐患。如果process()本身或process()内部调用的函数抛出异常，那么后两个释放资源的操作便不会执行。
当然我们可以将process()置于try块内，在catch释放完内存在throw出异常，但这样用于释放内存的代码便要出现两次。而且，捕捉异常、释放资源、重抛异常，这些操作会使异常处理例程的搜寻时间更加延长。

对此Bjarne Stroustrup引入了资源管理的手法，对对象而言，初始化操作发生于constructor内，资源的索求亦应在constructor内完成。资源的释放则应该在destructor
内完成。

```c++
#include<memory>
void f() {
    auto_ptr<int> p(new int);
    MutexLock Ml(m);
    process(p);
}
```
auto_ptr是标准库提供的class template 。它会自动delete通过new表达式配置的对象。使用它应包含memory头文件。恩，我决定将该模板的定义抄下来：

```c++
template<typename _Tp>

class auto_ptr

{

private:

    _Tp* _M_ptr;



public:

    typedef _Tp element_type;



    explicit

        auto_ptr(element_type* __p = 0) throw() : _M_ptr(__p) { }

    auto_ptr(auto_ptr& __a) throw() : _M_ptr(__a.release()) { }


    template<typename _Tp1>

    auto_ptr(auto_ptr<_Tp1>& __a) throw() : _M_ptr(__a.release()) { }



    auto_ptr&

        operator=(auto_ptr& __a) throw()

    {

        reset(__a.release());

        return *this;

    }



    template<typename _Tp1>

    auto_ptr&

        operator=(auto_ptr<_Tp1>& __a) throw()

    {

        reset(__a.release());

        return *this;

    }

    ~auto_ptr() { delete _M_ptr; }


    element_type&

        operator*() const throw() 

    {

        _GLIBCXX_DEBUG_ASSERT(_M_ptr != 0);

        return *_M_ptr; 

    }

    element_type*

        operator->() const throw() 

    {

        _GLIBCXX_DEBUG_ASSERT(_M_ptr != 0);

        return _M_ptr; 

    }

    element_type*

        get() const throw() { return _M_ptr; }

    element_type*

        release() throw()

    {

        element_type* __tmp = _M_ptr;

        _M_ptr = 0;

        return __tmp;

    }

    void reset(element_type* __p = 0) throw()


    {

        if (__p != _M_ptr)

        {

            delete _M_ptr;

            _M_ptr = __p;

        }

    }

    auto_ptr(auto_ptr_ref<element_type> __ref) throw()

        : _M_ptr(__ref._M_ptr) { }



    auto_ptr&

        operator=(auto_ptr_ref<element_type> __ref) throw()

    {

        if (__ref._M_ptr != this->get())

        {

            delete _M_ptr;

            _M_ptr = __ref._M_ptr;

        }

        return *this;

    }



    template<typename _Tp1>

    operator auto_ptr_ref<_Tp1>() throw()

    { return auto_ptr_ref<_Tp1>(this->release()); }



    template<typename _Tp1>

    operator auto_ptr<_Tp1>() throw()

    { return auto_ptr<_Tp1>(this->release()); }

};
```


可见其重载了*、->、=运算符，可像正常指针那样使用。而MutexLock是作者自己定义的类。一样，也析构函数中释放了对象。为什么要这样呢？因为**在异常处理机制终结某个函数之前，c++保证函数中的所有局部对象的destructor都会被调用。**

# 标准异常
本节对于标准异常及stringstream的说明少之又少，我想一个初学者一定是会有很大疑问的。要弄懂还要看别的说啊。
内存总有耗尽的时候，当内存已满时，我们无法new出空间，此时new语句会抛出bad_alloc的异常。如：

```c++
ptext=new vector<string>;
```

若是成功申请内存，随之会调用vector<string> default constructor应用于该heap对象上。然后再将其地址传给ptext。不论是否抛出异常都需要设置try块及相应的catch子句。若我们不想让其抛出异常，可这么写：
ptext=new （nothrow）vector<string>;这样，若new失败，则会传出0，ptext便会被设置为0。
标准库程序定义了一套异常类，其最根部是名为exception的抽象基类。exception声明有一个what()虚函数，可返回一个const char * ，用以描述异常信息。
当然，我们可以自己设计一个继承自exception的异常类，如：

```c++
#include <exception>
class iterator_overflow :public exception {
public:
    iterator_overflow(int index,int max):_index(index),_max(max){ }
    int index(){return _index;}
    int max(){return _mac;}
    const char * what() const;
private:
    int _index;
    int _max;
};
```

将iterator_overflow融入标准的exception类体系中的好处是，它可以被任何“打算捕捉抽象基类exception”的程序代码所捕捉，包括先前的iterator_overflow，这意味着我们不必改写原有程序代码。就可以让那些程序代码认识这个class。

```c++
catch(const exception &ex){
    cerr<<ex.what()<<endl;
}
```

会捕捉exception的所有派生类。

关于stringstream不多说了，书上给的太少，就这样了。

终于完事了。



